Workbook

Sheet ⚙ Config
A1: ⚙ CONFIGURATION CENTRE — Departments · Equipment · Lookup Lists
A2: Edit lists here — all dropdowns across every sheet update automatically. Add new rows; never leave blank gaps.
A4: DEPARTMENTS (Edit / Add here) | C4: EQUIPMENT TYPES (Edit / Add here) | E4: ITEM STATUS | G4: PRIORITY | I4: RESOLUTION | K4: PORT STATUS | M4: PORT TYPES | O4: MONTHS | P4: MULTI-SITE GUIDE
A5: School | C5: Desktop Computer | E5: ✅ Resolved | G5: 🔴 Critical | I5: Yes | K5: ✅ Active | M5: RJ45 Cat5e | O5: January | P5: 1. Fill 📋 Cover sheet per visit (client, site, date, tech)
A6: Homes | C6: Laptop | E6: 🔄 In Progress | G6: 🟠 High | I6: No | K6: ❌ Dead/No Link | M6: RJ45 Cat6 | O6: February | P6: 2. Add/edit Departments in column A for this client
A7: Education | C7: CCTV Camera | E7: ❌ Unresolved | G7: 🟡 Medium | I7: Partial | K7: 🔄 Intermittent | M7: Fibre | O7: March | P7: 3. Add custom equipment in column C
A8: Finance | C8: Printer | E8: 🔁 Recurring | G8: 🟢 Low | K8: 🔌 Not Patched | M8: WiFi/AP | O8: April | P8: 4. All dropdowns update automatically across all sheets
A9: Procurement | C9: Access Point | E9: ⏳ Pending Parts | K9: 🔒 Disabled | M9: PoE | O9: May | P9: 5. NEW SITE: File → Make a Copy → rename → update Cover + Depts
A10: Farm & Business | C10: Network Switch | K10: 🔧 Re-terminate | M10: SFP | O10: June | P10: 6. Each copy = one complete signed client report
A11: Clinic | C11: Router | M11: Coax | O11: July
A12: HR | C12: UPS/Power Backup | O12: August
A13: Church | C13: Monitor | O13: September
A14: Admin | C14: Keyboard & Mouse | O14: October
A15: Teams & Guests | C15: Server | O15: November
A16: Central Kitchen | C16: NVR/DVR | O16: December
A17: ← Type new dept here | C17: Projector
C18: Tablet
C19: IP Phone
C20: Photocopier
C21: Scanner
C22: External Hard Drive
C23: Flash Drive
C24: Smart TV
C25: OTHER (specify in notes)
C26: ← Add custom equipment

Sheet 📋 Site Cover
A1: 🔧 IT MAINTENANCE & SUPPORT — SITE VISIT REPORT
A2: Complete this cover page first — all other sheets pull from here automatically
A4: Client / Organisation:
A5: Site / Location:
A6: Building / Block / Floor:
A7: Visit Date (YYYY-MM-DD): | C7: =TODAY() | H7: Year: | J7: Month: | L7: Day:
A8: Visit Reference #:
A9: Contract / PO Number:
A10: Lead Technician:
A11: Assistant(s):
A12: Client Representative:
A13: Client Designation:
A14: Phone / Email:
A15: Time Out:
A16: Next Scheduled Visit:
A18: SCOPE OF THIS VISIT (replace ☐ with ✓ for applicable items)
C19: ☐ General IT Support | F19: ☐ Network / Cabling Audit | I19: ☐ CCTV / NVR Check | L19: ☐ Printer Maintenance
C20: ☐ Access Point Config | F20: ☐ Server / UPS Check | I20: ☐ Laptop / Desktop | L20: ☐ Software / OS Issues
C21: ☐ New Equipment Setup | F21: ☐ User Training | I21: ☐ Procurement / Quote | L21: ☐ Emergency Callout
A23: OVERALL VISIT SUMMARY / NOTES
A30: ━━ REPORT ACKNOWLEDGEMENT & SIGN-OFF ━━
A31: 🔧 TECHNICIAN / ENGINEER | H31: ✅ CLIENT / ADMIN COUNTER-SIGNATURE
A32: Name: ___________________________ Signature: ___________________________ Date: _______________ | H32: Name: ___________________________ Designation: ___________________________ Signature: ___________________________ Date: _______________
A34: DECLARATION
A35: I/We confirm that issues, actions and findings documented in this report are accurate and reflect the work carried out during this visit. Outstanding items have been communicated. Both parties agree to the contents of this report.
A37: Confidential — IT Support Site Report | Do not distribute without authorisation

Sheet 📝 Visit Log
A1: 📝 SITE VISIT LOG — ISSUE & RESOLUTION TRACKER
A2: One row per issue. Select Department & Equipment from dropdowns. Network Point auto-fills details from Network Audit.
A3: Date: | C3: ='📋 Site Cover'!C7 | D3: Technician: | G3: ='📋 Site Cover'!C10 | H3: Visit Ref: | L3: Client: | M3: ='📋 Site Cover'!C4 | P3: Ref #: | Q3: ='📋 Site Cover'!C8
A5: STATUS: ✅ Resolved 🔄 In Progress ❌ Unresolved 🔁 Recurring ⏳ Pending Parts | PRIORITY: 🔴 Critical 🟠 High 🟡 Medium 🟢 Low
A7: 💡 TIP: Enter the Network Point ID in column E — Device Type, Location & Connected-To will auto-fill from the Network Points Audit sheet
A8: # | B8: Department | C8: Sub-Area / Room | D8: Item / Equipment | E8: Network Point ID (auto-fill →) | F8: Auto: Device Location | G8: Auto: Connected To | H8: Issue Description | I8: Root Cause | J8: Action Taken | K8: Status | L8: Resolved | M8: Res. Time (hrs) | N8: Parts / Materials Used | O8: Parts Cost | P8: Further Request | Q8: Priority | R8: Follow-up Date | S8: Remarks
A9: 1 | F9: =IFERROR(VLOOKUP(E9,'🌐 Network Points'!$B$8:$J$107,3,0),"") | G9: =IFERROR(VLOOKUP(E9,'🌐 Network Points'!$B$8:$J$107,5,0),"")
A10: 2 | F10: =IFERROR(VLOOKUP(E10,'🌐 Network Points'!$B$8:$J$107,3,0),"") | G10: =IFERROR(VLOOKUP(E10,'🌐 Network Points'!$B$8:$J$107,5,0),"")
A11: 3 | F11: =IFERROR(VLOOKUP(E11,'🌐 Network Points'!$B$8:$J$107,3,0),"") | G11: =IFERROR(VLOOKUP(E11,'🌐 Network Points'!$B$8:$J$107,5,0),"")
A12: 4 | F12: =IFERROR(VLOOKUP(E12,'🌐 Network Points'!$B$8:$J$107,3,0),"") | G12: =IFERROR(VLOOKUP(E12,'🌐 Network Points'!$B$8:$J$107,5,0),"")
A13: 5 | F13: =IFERROR(VLOOKUP(E13,'🌐 Network Points'!$B$8:$J$107,3,0),"") | G13: =IFERROR(VLOOKUP(E13,'🌐 Network Points'!$B$8:$J$107,5,0),"")
A14: 6 | F14: =IFERROR(VLOOKUP(E14,'🌐 Network Points'!$B$8:$J$107,3,0),"") | G14: =IFERROR(VLOOKUP(E14,'🌐 Network Points'!$B$8:$J$107,5,0),"")
A15: 7 | F15: =IFERROR(VLOOKUP(E15,'🌐 Network Points'!$B$8:$J$107,3,0),"") | G15: =IFERROR(VLOOKUP(E15,'🌐 Network Points'!$B$8:$J$107,5,0),"")
A16: 8 | F16: =IFERROR(VLOOKUP(E16,'🌐 Network Points'!$B$8:$J$107,3,0),"") | G16: =IFERROR(VLOOKUP(E16,'🌐 Network Points'!$B$8:$J$107,5,0),"")
A17: 9 | F17: =IFERROR(VLOOKUP(E17,'🌐 Network Points'!$B$8:$J$107,3,0),"") | G17: =IFERROR(VLOOKUP(E17,'🌐 Network Points'!$B$8:$J$107,5,0),"")
A18: 10 | F18: =IFERROR(VLOOKUP(E18,'🌐 Network Points'!$B$8:$J$107,3,0),"") | G18: =IFERROR(VLOOKUP(E18,'🌐 Network Points'!$B$8:$J$107,5,0),"")
A19: 11 | F19: =IFERROR(VLOOKUP(E19,'🌐 Network Points'!$B$8:$J$107,3,0),"") | G19: =IFERROR(VLOOKUP(E19,'🌐 Network Points'!$B$8:$J$107,5,0),"")
A20: 12 | F20: =IFERROR(VLOOKUP(E20,'🌐 Network Points'!$B$8:$J$107,3,0),"") | G20: =IFERROR(VLOOKUP(E20,'🌐 Network Points'!$B$8:$J$107,5,0),"")
... A108: 100 | F108: =IFERROR(VLOOKUP(E108,'🌐 Network Points'!$B$8:$J$107,3,0),"") | G108: =IFERROR(VLOOKUP(E108,'🌐 Network Points'!$B$8:$J$107,5,0),"")
A109: TOTALS | E109: Total Issues: | F109: =COUNTA(H9:H108) | G109: Resolved: | H109: =COUNTIF(L9:L108,"Yes") | I109: Unresolved: | J109: =COUNTIF(L9:L108,"No") | K109: Avg Hrs: | L109: =IFERROR(AVERAGE(M9:M108),0) | M109: Parts Cost: | N109: =SUM(O9:O108) | O109: Critical: | P109: =COUNTIF(Q9:Q108,"🔴 Critical")
A111: ━━ REPORT ACKNOWLEDGEMENT & SIGN-OFF ━━
A112: 🔧 TECHNICIAN / ENGINEER | J112: ✅ CLIENT / ADMIN COUNTER-SIGNATURE
A113: Name: ___________________________ Signature: ___________________________ Date: _______________ | J113: Name: ___________________________ Designation: ___________________________ Signature: ___________________________ Date: _______________
A115: DECLARATION
A116: I/We confirm that issues, actions and findings documented in this report are accurate and reflect the work carried out during this visit. Outstanding items have been communicated. Both parties agree to the contents of this report.

Sheet 🌐 Network Points
A1: 🌐 NETWORK POINTS WALKTHROUGH — OFFICE-BY-OFFICE AUDIT
A2: Walk each office with the admin. Point IDs entered here auto-fill into the Visit Log.
A3: Date: | C3: ='📋 Site Cover'!C7 | D3: Admin with you: | F3: ='📋 Site Cover'!C12 | G3: Site: | I3: ='📋 Site Cover'!C5
A5: PORT STATUS: ✅ Active ❌ Dead/No Link 🔄 Intermittent 🔌 Not Patched 🔒 Disabled 🔧 Re-terminate
A6: 💡 The 'Point ID' (col B) is the KEY — type it in Visit Log col E to auto-pull device location and connection details
A7: # | B7: Point ID (e.g. AP-01, SW-A2) | C7: Office / Room | D7: Department | E7: Device Type | F7: Connected To (Switch/AP/Router) | G7: Switch Port # / VLAN | H7: Port Status | I7: Speed (Mbps) | J7: Issue / Remarks
A8: 1
A9: 2
A10: 3
A11: 4
A12: 5
A13: 6
A14: 7
A15: 8
A16: 9
A17: 10
A18: 11
A19: 12
... A107: 100
A108: TOTALS | C108: Checked: | D108: =COUNTA(B8:B107) | E108: Active: | F108: =COUNTIF(H8:H107,"✅ Active") | G108: Issues: | H108: =COUNTIFS(H8:H107,"<>"&"✅ Active",H8:H107,"<>"&"") | I108: Need Action: | J108: =COUNTIF(J8:J107,"<>"&"")
A110: ━━ REPORT ACKNOWLEDGEMENT & SIGN-OFF ━━
A111: 🔧 TECHNICIAN / ENGINEER | F111: ✅ CLIENT / ADMIN COUNTER-SIGNATURE
A112: Name: ___________________________ Signature: ___________________________ Date: _______________ | F112: Name: ___________________________ Designation: ___________________________ Signature: ___________________________ Date: _______________
A114: DECLARATION
A115: I/We confirm that issues, actions and findings documented in this report are accurate and reflect the work carried out during this visit. Outstanding items have been communicated. Both parties agree to the contents of this report.

Sheet 🖥 Equipment Register
A1: 🖥 EQUIPMENT REGISTER — ASSET INVENTORY
A2: Log all IT assets. Use 'OTHER (specify in notes)' for unlisted equipment and describe in the Notes column.
A4: # | B4: Department | C4: Location/Room | D4: Item Type | E4: Custom Item (if OTHER) | F4: Make / Model | G4: Serial Number | H4: Asset Tag | I4: Condition | J4: Purchase Date | K4: Warranty Exp. | L4: Assigned To | M4: Notes
A5: 1
A6: 2
A7: 3
A8: 4
A9: 5
A10: 6
A11: 7
A12: 8
A13: 9
A14: 10
A15: 11
A16: 12
... A104: 100

Sheet 🔐 Credentials
A1: 🔐 DEVICE CREDENTIALS & NETWORK REGISTRY
A2: CONFIDENTIAL — Restrict access. Store passwords using encoded/masked format where possible.
A4: ⚠ SECURITY NOTICE: This sheet contains sensitive credentials. Limit access to authorised IT personnel only. Consider using a password manager for live credentials — store only partial/masked passwords here (e.g. ••••••Admin1 or first 3 + last 2 chars). Lock this sheet with a password via Review → Protect Sheet before sharing the file.
A6: 🌐 SECTION 1: ROUTERS & FIREWALLS
A7: # | B7: Department / Location | C7: Device Label (e.g. RTR-01) | D7: Make / Model | E7: WAN IP Address | F7: LAN IP Address | G7: Subnet Mask | H7: Default Gateway | I7: Admin URL / Access Method | J7: Admin Username | K7: Admin Password (mask: ••••xx) | L7: Firmware Version | M7: Last Changed | N7: Notes
A8: 1
A9: 2
A10: 3
A11: 4
A12: 5
A13: 6
A14: 7
A15: 8
A16: 9
A17: 10
A18: 11
A19: 12
... A27: 20
A29: 📶 SECTION 2: WIFI ACCESS POINTS — SSID & PASSWORDS
A30: # | B30: Department / Location | C30: AP Label (e.g. AP-01) | D30: Make / Model | E30: AP IP Address | F30: MAC Address | G30: SSID (Network Name) | H30: WiFi Password (mask: ••••xx) | I30: Security Type (WPA2/WPA3) | J30: WiFi Band (2.4/5GHz) | K30: VLAN / Network | L30: Admin Username | M30: Admin Password (mask: ••••xx) | N30: Last Changed | O30: Notes
A31: 1
A32: 2
A33: 3
A34: 4
A35: 5
A36: 6
A37: 7
A38: 8
A39: 9
A40: 10
A41: 11
A42: 12
... A55: 25
A57: 📷 SECTION 3: NVR / DVR — CCTV SYSTEMS
A58: # | B58: Department / Location | C58: Device Label (e.g. NVR-01) | D58: Type (NVR/DVR) | E58: Make / Model | F58: IP Address | G58: MAC Address | H58: No. of Channels | I58: No. of Cameras Active | J58: Admin Username | K58: Admin Password (mask: ••••xx) | L58: Remote View App / URL | M58: Remote View Username | N58: Remote View Password (mask) | O58: HDD Size (TB) | P58: Recording Retention (days) | Q58: Last Changed | R58: Notes
A59: 1
A60: 2
A61: 3
A62: 4
A63: 5
...

Sheet 📌 Further Requests
A1: 📌 FURTHER REQUESTS & FOLLOW-UP TRACKER
A2: Log all pending tasks, hardware requests, upgrades and follow-ups from this visit.
A4: # | B4: Department | C4: Request Description | D4: Item Required | E4: Custom Item (if not listed) | F4: Est. Cost | G4: Priority | H4: Requested By | I4: Due Date | J4: Progress | K4: Notes / Response
A5: 1
A6: 2
A7: 3
A8: 4
A9: 5
A10: 6
A11: 7
A12: 8
A13: 9
A14: 10
A15: 11
A16: 12
... A104: 100

Sheet 📅 Weekly Report
A1: 📅 WEEKLY SUPPORT REPORT
A2: Auto-summary of visit activity for the selected week. Select Week and Year below.
A3: Select Week: | E3: Year: | I3: Client: | J3: ='📋 Site Cover'!C4
A5: KEY METRICS THIS WEEK
A6: Total Issues | C6: Resolved | E6: Unresolved | G6: In Progress | I6: Critical | K6: Parts Cost (KES) | M6: Avg Resolution Time
A7: =COUNTA('📝 Visit Log'!H9:H108) | C7: =COUNTIF('📝 Visit Log'!L9:L108,"Yes") | E7: =COUNTIF('📝 Visit Log'!L9:L108,"No") | G7: =COUNTIF('📝 Visit Log'!K9:K108,"🔄 In Progress") | I7: =COUNTIF('📝 Visit Log'!Q9:Q108,"🔴 Critical") | K7: =SUM('📝 Visit Log'!O9:O108) | M7: =IFERROR(AVERAGE('📝 Visit Log'!M9:M108),0)
A9: DEPARTMENT BREAKDOWN
A10: Department | C10: Issues | E10: Resolved | G10: Unresolved | I10: Critical | K10: Further Requests
A11: School | C11: =COUNTIF('📝 Visit Log'!$B$9:$B$108,A11) | E11: =COUNTIFS('📝 Visit Log'!$B$9:$B$108,A11,'📝 Visit Log'!$L$9:$L$108,"Yes") | G11: =COUNTIFS('📝 Visit Log'!$B$9:$B$108,A11,'📝 Visit Log'!$L$9:$L$108,"No") | I11: =COUNTIFS('📝 Visit Log'!$B$9:$B$108,A11,'📝 Visit Log'!$Q$9:$Q$108,"🔴 Critical") | K11: =COUNTIFS('📝 Visit Log'!$B$9:$B$108,A11,'📝 Visit Log'!$P$9:$P$108,"<>"&"")
A12: Homes | C12: =COUNTIF('📝 Visit Log'!$B$9:$B$108,A12) | E12: =COUNTIFS('📝 Visit Log'!$B$9:$B$108,A12,'📝 Visit Log'!$L$9:$L$108,"Yes") | G12: =COUNTIFS('📝 Visit Log'!$B$9:$B$108,A12,'📝 Visit Log'!$L$9:$L$108,"No") | I12: =COUNTIFS('📝 Visit Log'!$B$9:$B$108,A12,'📝 Visit Log'!$Q$9:$Q$108,"🔴 Critical") | K12: =COUNTIFS('📝 Visit Log'!$B$9:$B$108,A12,'📝 Visit Log'!$P$9:$P$108,"<>"&"")
A13: Education | C13: =COUNTIF('📝 Visit Log'!$B$9:$B$108,A13) | E13: =COUNTIFS('📝 Visit Log'!$B$9:$B$108,A13,'📝 Visit Log'!$L$9:$L$108,"Yes") | G13: =COUNTIFS('📝 Visit Log'!$B$9:$B$108,A13,'📝 Visit Log'!$L$9:$L$108,"No") | I13: =COUNTIFS('📝 Visit Log'!$B$9:$B$108,A13,'📝 Visit Log'!$Q$9:$Q$108,"🔴 Critical") | K13: =COUNTIFS('📝 Visit Log'!$B$9:$B$108,A13,'📝 Visit Log'!$P$9:$P$108,"<>"&"")
A14: Finance | C14: =COUNTIF('📝 Visit Log'!$B$9:$B$108,A14) | E14: =COUNTIFS('📝 Visit Log'!$B$9:$B$108,A14,'📝 Visit Log'!$L$9:$L$108,"Yes") | G14: =COUNTIFS('📝 Visit Log'!$B$9:$B$108,A14,'📝 Visit Log'!$L$9:$L$108,"No") | I14: =COUNTIFS('📝 Visit Log'!$B$9:$B$108,A14,'📝 Visit Log'!$Q$9:$Q$108,"🔴 Critical") | K14: =COUNTIFS('📝 Visit Log'!$B$9:$B$108,A14,'📝 Visit Log'!$P$9:$P$108,"<>"&"")
A15: Procurement | C15: =COUNTIF('📝 Visit Log'!$B$9:$B$108,A15) | E15: =COUNTIFS('📝 Visit Log'!$B$9:$B$108,A15,'📝 Visit Log'!$L$9:$L$108,"Yes") | G15: =COUNTIFS('📝 Visit Log'!$B$9:$B$108,A15,'📝 Visit Log'!$L$9:$L$108,"No") | I15: =COUNTIFS('📝 Visit Log'!$B$9:$B$108,A15,'📝 Visit Log'!$Q$9:$Q$108,"🔴 Critical") | K15: =COUNTIFS('📝 Visit Log'!$B$9:$B$108,A15,'📝 Visit Log'!$P$9:$P$108,"<>"&"")
A16: Farm & Business | C16: =COUNTIF('📝 Visit Log'!$B$9:$B$108,A16) | E16: =COUNTIFS('📝 Visit Log'!$B$9:$B$108,A16,'📝 Visit Log'!$L$9:$L$108,"Yes") | G16: =COUNTIFS('📝 Visit Log'!$B$9:$B$108,A16,'📝 Visit Log'!$L$9:$L$108,"No") | I16: =COUNTIFS('📝 Visit Log'!$B$9:$B$108,A16,'📝 Visit Log'!$Q$9:$Q$108,"🔴 Critical") | K16: =COUNTIFS('📝 Visit Log'!$B$9:$B$108,A16,'📝 Visit Log'!$P$9:$P$108,"<>"&"")
A17: Clinic | C17: =COUNTIF('📝 Visit Log'!$B$9:$B$108,A17) | E17: =COUNTIFS('📝 Visit Log'!$B$9:$B$108,A17,'📝 Visit Log'!$L$9:$L$108,"Yes") | G17: =COUNTIFS('📝 Visit Log'!$B$9:$B$108,A17,'📝 Visit Log'!$L$9:$L$108,"No") | I17: =COUNTIFS('📝 Visit Log'!$B$9:$B$108,A17,'📝 Visit Log'!$Q$9:$Q$108,"🔴 Critical") | K17: =COUNTIFS('📝 Visit Log'!$B$9:$B$108,A17,'📝 Visit Log'!$P$9:$P$108,"<>"&"")
A18: HR | C18: =COUNTIF('📝 Visit Log'!$B$9:$B$108,A18) | E18: =COUNTIFS('📝 Visit Log'!$B$9:$B$108,A18,'📝 Visit Log'!$L$9:$L$108,"Yes") | G18: =COUNTIFS('📝 Visit Log'!$B$9:$B$108,A18,'📝 Visit Log'!$L$9:$L$108,"No") | I18: =COUNTIFS('📝 Visit Log'!$B$9:$B$108,A18,'📝 Visit Log'!$Q$9:$Q$108,"🔴 Critical") | K18: =COUNTIFS('📝 Visit Log'!$B$9:$B$108,A18,'📝 Visit Log'!$P$9:$P$108,"<>"&"")
A19: Church | C19: =COUNTIF('📝 Visit Log'!$B$9:$B$108,A19) | E19: =COUNTIFS('📝 Visit Log'!$B$9:$B$108,A19,'📝 Visit Log'!$L$9:$L$108,"Yes") | G19: =COUNTIFS('📝 Visit Log'!$B$9:$B$108,A19,'📝 Visit Log'!$L$9:$L$108,"No") | I19: =COUNTIFS('📝 Visit Log'!$B$9:$B$108,A19,'📝 Visit Log'!$Q$9:$Q$108,"🔴 Critical") | K19: =COUNTIFS('📝 Visit Log'!$B$9:$B$108,A19,'📝 Visit Log'!$P$9:$P$108,"<>"&"")
A20: Admin | C20: =COUNTIF('📝 Visit Log'!$B$9:$B$108,A20) | E20: =COUNTIFS('📝 Visit Log'!$B$9:$B$108,A20,'📝 Visit Log'!$L$9:$L$108,"Yes") | G20: =COUNTIFS('📝 Visit Log'!$B$9:$B$108,A20,'📝 Visit Log'!$L$9:$L$108,"No") | I20: =COUNTIFS('📝 Visit Log'!$B$9:$B$108,A20,'📝 Visit Log'!$Q$9:$Q$108,"🔴 Critical") | K20: =COUNTIFS('📝 Visit Log'!$B$9:$B$108,A20,'📝 Visit Log'!$P$9:$P$108,"<>"&"")
A21: Teams & Guests | C21: =COUNTIF('📝 Visit Log'!$B$9:$B$108,A21) | E21: =COUNTIFS('📝 Visit Log'!$B$9:$B$108,A21,'📝 Visit Log'!$L$9:$L$108,"Yes") | G21: =COUNTIFS('📝 Visit Log'!$B$9:$B$108,A21,'📝 Visit Log'!$L$9:$L$108,"No") | I21: =COUNTIFS('📝 Visit Log'!$B$9:$B$108,A21,'📝 Visit Log'!$Q$9:$Q$108,"🔴 Critical") | K21: =COUNTIFS('📝 Visit Log'!$B$9:$B$108,A21,'📝 Visit Log'!$P$9:$P$108,"<>"&"")
A22: Central Kitchen | C22: =COUNTIF('📝 Visit Log'!$B$9:$B$108,A22) | E22: =COUNTIFS('📝 Visit Log'!$B$9:$B$108,A22,'📝 Visit Log'!$L$9:$L$108,"Yes") | G22: =COUNTIFS('📝 Visit Log'!$B$9:$B$108,A22,'📝 Visit Log'!$L$9:$L$108,"No") | I22: =COUNTIFS('📝 Visit Log'!$B$9:$B$108,A22,'📝 Visit Log'!$Q$9:$Q$108,"🔴 Critical") | K22: =COUNTIFS('📝 Visit Log'!$B$9:$B$108,A22,'📝 Visit Log'!$P$9:$P$108,"<>"&"")
A24: ━━ REPORT ACKNOWLEDGEMENT & SIGN-OFF ━━
A25: 🔧 TECHNICIAN / ENGINEER | H25: ✅ CLIENT / ADMIN COUNTER-SIGNATURE
A26: Name: ___________________________ Signature: ___________________________ Date: _______________ | H26: Name: ___________________________ Designation: ___________________________ Signature: ___________________________ Date: _______________
A28: DECLARATION
A29: I/We confirm that issues, actions and findings documented in this report are accurate and reflect the work carried out during this visit. Outstanding items have been communicated. Both parties agree to the contents of this report.

Sheet 📆 Monthly Report
A1: 📆 MONTHLY SUPPORT REPORT
A2: Monthly summary across all departments. Select Month and Year.
A3: Select Month: | E3: Year: | I3: Client: | J3: ='📋 Site Cover'!C4
A5: MONTHLY KEY METRICS
A6: Total Issues | C6: Resolved | E6: Unresolved | G6: In Progress | I6: Critical | K6: Parts Cost (KES) | M6: Avg Resolution Time
A7: =COUNTA('📝 Visit Log'!H9:H108) | C7: =COUNTIF('📝 Visit Log'!L9:L108,"Yes") | E7: =COUNTIF('📝 Visit Log'!L9:L108,"No") | G7: =COUNTIF('📝 Visit Log'!K9:K108,"🔄 In Progress") | I7: =COUNTIF('📝 Visit Log'!Q9:Q108,"🔴 Critical") | K7: =SUM('📝 Visit Log'!O9:O108) | M7: =IFERROR(AVERAGE('📝 Visit Log'!M9:M108),0)
A9: MONTHLY DEPARTMENT BREAKDOWN
A10: Department | C10: Total Issues | E10: Resolved | G10: Unresolved | I10: In Progress | K10: Critical | M10: Parts Cost | O10: Further Requests
A11: School | C11: =COUNTIF('📝 Visit Log'!$B$9:$B$108,A11) | E11: =COUNTIFS('📝 Visit Log'!$B$9:$B$108,A11,'📝 Visit Log'!$L$9:$L$108,"Yes") | G11: =COUNTIFS('📝 Visit Log'!$B$9:$B$108,A11,'📝 Visit Log'!$L$9:$L$108,"No") | I11: =COUNTIFS('📝 Visit Log'!$B$9:$B$108,A11,'📝 Visit Log'!$K$9:$K$108,"🔄 In Progress") | K11: =COUNTIFS('📝 Visit Log'!$B$9:$B$108,A11,'📝 Visit Log'!$Q$9:$Q$108,"🔴 Critical") | M11: =SUMIF('📝 Visit Log'!$B$9:$B$108,A11,'📝 Visit Log'!$O$9:$O$108) | O11: =COUNTIFS('📝 Visit Log'!$B$9:$B$108,A11,'📝 Visit Log'!$P$9:$P$108,"<>"&"")
A12: Homes | C12: =COUNTIF('📝 Visit Log'!$B$9:$B$108,A12) | E12: =COUNTIFS('📝 Visit Log'!$B$9:$B$108,A12,'📝 Visit Log'!$L$9:$L$108,"Yes") | G12: =COUNTIFS('📝 Visit Log'!$B$9:$B$108,A12,'📝 Visit Log'!$L$9:$L$108,"No") | I12: =COUNTIFS('📝 Visit Log'!$B$9:$B$108,A12,'📝 Visit Log'!$K$9:$K$108,"🔄 In Progress") | K12: =COUNTIFS('📝 Visit Log'!$B$9:$B$108,A12,'📝 Visit Log'!$Q$9:$Q$108,"🔴 Critical") | M12: =SUMIF('📝 Visit Log'!$B$9:$B$108,A12,'📝 Visit Log'!$O$9:$O$108) | O12: =COUNTIFS('📝 Visit Log'!$B$9:$B$108,A12,'📝 Visit Log'!$P$9:$P$108,"<>"&"")
A13: Education | C13: =COUNTIF('📝 Visit Log'!$B$9:$B$108,A13) | E13: =COUNTIFS('📝 Visit Log'!$B$9:$B$108,A13,'📝 Visit Log'!$L$9:$L$108,"Yes") | G13: =COUNTIFS('📝 Visit Log'!$B$9:$B$108,A13,'📝 Visit Log'!$L$9:$L$108,"No") | I13: =COUNTIFS('📝 Visit Log'!$B$9:$B$108,A13,'📝 Visit Log'!$K$9:$K$108,"🔄 In Progress") | K13: =COUNTIFS('📝 Visit Log'!$B$9:$B$108,A13,'📝 Visit Log'!$Q$9:$Q$108,"🔴 Critical") | M13: =SUMIF('📝 Visit Log'!$B$9:$B$108,A13,'📝 Visit Log'!$O$9:$O$108) | O13: =COUNTIFS('📝 Visit Log'!$B$9:$B$108,A13,'📝 Visit Log'!$P$9:$P$108,"<>"&"")
A14: Finance | C14: =COUNTIF('📝 Visit Log'!$B$9:$B$108,A14) | E14: =COUNTIFS('📝 Visit Log'!$B$9:$B$108,A14,'📝 Visit Log'!$L$9:$L$108,"Yes") | G14: =COUNTIFS('📝 Visit Log'!$B$9:$B$108,A14,'📝 Visit Log'!$L$9:$L$108,"No") | I14: =COUNTIFS('📝 Visit Log'!$B$9:$B$108,A14,'📝 Visit Log'!$K$9:$K$108,"🔄 In Progress") | K14: =COUNTIFS('📝 Visit Log'!$B$9:$B$108,A14,'📝 Visit Log'!$Q$9:$Q$108,"🔴 Critical") | M14: =SUMIF('📝 Visit Log'!$B$9:$B$108,A14,'📝 Visit Log'!$O$9:$O$108) | O14: =COUNTIFS('📝 Visit Log'!$B$9:$B$108,A14,'📝 Visit Log'!$P$9:$P$108,"<>"&"")
A15: Procurement | C15: =COUNTIF('📝 Visit Log'!$B$9:$B$108,A15) | E15: =COUNTIFS('📝 Visit Log'!$B$9:$B$108,A15,'📝 Visit Log'!$L$9:$L$108,"Yes") | G15: =COUNTIFS('📝 Visit Log'!$B$9:$B$108,A15,'📝 Visit Log'!$L$9:$L$108,"No") | I15: =COUNTIFS('📝 Visit Log'!$B$9:$B$108,A15,'📝 Visit Log'!$K$9:$K$108,"🔄 In Progress") | K15: =COUNTIFS('📝 Visit Log'!$B$9:$B$108,A15,'📝 Visit Log'!$Q$9:$Q$108,"🔴 Critical") | M15: =SUMIF('📝 Visit Log'!$B$9:$B$108,A15,'📝 Visit Log'!$O$9:$O$108) | O15: =COUNTIFS('📝 Visit Log'!$B$9:$B$108,A15,'📝 Visit Log'!$P$9:$P$108,"<>"&"")
A16: Farm & Business | C16: =COUNTIF('📝 Visit Log'!$B$9:$B$108,A16) | E16: =COUNTIFS('📝 Visit Log'!$B$9:$B$108,A16,'📝 Visit Log'!$L$9:$L$108,"Yes") | G16: =COUNTIFS('📝 Visit Log'!$B$9:$B$108,A16,'📝 Visit Log'!$L$9:$L$108,"No") | I16: =COUNTIFS('📝 Visit Log'!$B$9:$B$108,A16,'📝 Visit Log'!$K$9:$K$108,"🔄 In Progress") | K16: =COUNTIFS('📝 Visit Log'!$B$9:$B$108,A16,'📝 Visit Log'!$Q$9:$Q$108,"🔴 Critical") | M16: =SUMIF('📝 Visit Log'!$B$9:$B$108,A16,'📝 Visit Log'!$O$9:$O$108) | O16: =COUNTIFS('📝 Visit Log'!$B$9:$B$108,A16,'📝 Visit Log'!$P$9:$P$108,"<>"&"")
A17: Clinic | C17: =COUNTIF('📝 Visit Log'!$B$9:$B$108,A17) | E17: =COUNTIFS('📝 Visit Log'!$B$9:$B$108,A17,'📝 Visit Log'!$L$9:$L$108,"Yes") | G17: =COUNTIFS('📝 Visit Log'!$B$9:$B$108,A17,'📝 Visit Log'!$L$9:$L$108,"No") | I17: =COUNTIFS('📝 Visit Log'!$B$9:$B$108,A17,'📝 Visit Log'!$K$9:$K$108,"🔄 In Progress") | K17: =COUNTIFS('📝 Visit Log'!$B$9:$B$108,A17,'📝 Visit Log'!$Q$9:$Q$108,"🔴 Critical") | M17: =SUMIF('📝 Visit Log'!$B$9:$B$108,A17,'📝 Visit Log'!$O$9:$O$108) | O17: =COUNTIFS('📝 Visit Log'!$B$9:$B$108,A17,'📝 Visit Log'!$P$9:$P$108,"<>"&"")
A18: HR | C18: =COUNTIF('📝 Visit Log'!$B$9:$B$108,A18) | E18: =COUNTIFS('📝 Visit Log'!$B$9:$B$108,A18,'📝 Visit Log'!$L$9:$L$108,"Yes") | G18: =COUNTIFS('📝 Visit Log'!$B$9:$B$108,A18,'📝 Visit Log'!$L$9:$L$108,"No") | I18: =COUNTIFS('📝 Visit Log'!$B$9:$B$108,A18,'📝 Visit Log'!$K$9:$K$108,"🔄 In Progress") | K18: =COUNTIFS('📝 Visit Log'!$B$9:$B$108,A18,'📝 Visit Log'!$Q$9:$Q$108,"🔴 Critical") | M18: =SUMIF('📝 Visit Log'!$B$9:$B$108,A18,'📝 Visit Log'!$O$9:$O$108) | O18: =COUNTIFS('📝 Visit Log'!$B$9:$B$108,A18,'📝 Visit Log'!$P$9:$P$108,"<>"&"")
A19: Church | C19: =COUNTIF('📝 Visit Log'!$B$9:$B$108,A19) | E19: =COUNTIFS('📝 Visit Log'!$B$9:$B$108,A19,'📝 Visit Log'!$L$9:$L$108,"Yes") | G19: =COUNTIFS('📝 Visit Log'!$B$9:$B$108,A19,'📝 Visit Log'!$L$9:$L$108,"No") | I19: =COUNTIFS('📝 Visit Log'!$B$9:$B$108,A19,'📝 Visit Log'!$K$9:$K$108,"🔄 In Progress") | K19: =COUNTIFS('📝 Visit Log'!$B$9:$B$108,A19,'📝 Visit Log'!$Q$9:$Q$108,"🔴 Critical") | M19: =SUMIF('📝 Visit Log'!$B$9:$B$108,A19,'📝 Visit Log'!$O$9:$O$108) | O19: =COUNTIFS('📝 Visit Log'!$B$9:$B$108,A19,'📝 Visit Log'!$P$9:$P$108,"<>"&"")
A20: Admin | C20: =COUNTIF('📝 Visit Log'!$B$9:$B$108,A20) | E20: =COUNTIFS('📝 Visit Log'!$B$9:$B$108,A20,'📝 Visit Log'!$L$9:$L$108,"Yes") | G20: =COUNTIFS('📝 Visit Log'!$B$9:$B$108,A20,'📝 Visit Log'!$L$9:$L$108,"No") | I20: =COUNTIFS('📝 Visit Log'!$B$9:$B$108,A20,'📝 Visit Log'!$K$9:$K$108,"🔄 In Progress") | K20: =COUNTIFS('📝 Visit Log'!$B$9:$B$108,A20,'📝 Visit Log'!$Q$9:$Q$108,"🔴 Critical") | M20: =SUMIF('📝 Visit Log'!$B$9:$B$108,A20,'📝 Visit Log'!$O$9:$O$108) | O20: =COUNTIFS('📝 Visit Log'!$B$9:$B$108,A20,'📝 Visit Log'!$P$9:$P$108,"<>"&"")
A21: Teams & Guests | C21: =COUNTIF('📝 Visit Log'!$B$9:$B$108,A21) | E21: =COUNTIFS('📝 Visit Log'!$B$9:$B$108,A21,'📝 Visit Log'!$L$9:$L$108,"Yes") | G21: =COUNTIFS('📝 Visit Log'!$B$9:$B$108,A21,'📝 Visit Log'!$L$9:$L$108,"No") | I21: =COUNTIFS('📝 Visit Log'!$B$9:$B$108,A21,'📝 Visit Log'!$K$9:$K$108,"🔄 In Progress") | K21: =COUNTIFS('📝 Visit Log'!$B$9:$B$108,A21,'📝 Visit Log'!$Q$9:$Q$108,"🔴 Critical") | M21: =SUMIF('📝 Visit Log'!$B$9:$B$108,A21,'📝 Visit Log'!$O$9:$O$108) | O21: =COUNTIFS('📝 Visit Log'!$B$9:$B$108,A21,'📝 Visit Log'!$P$9:$P$108,"<>"&"")
A22: Central Kitchen | C22: =COUNTIF('📝 Visit Log'!$B$9:$B$108,A22) | E22: =COUNTIFS('📝 Visit Log'!$B$9:$B$108,A22,'📝 Visit Log'!$L$9:$L$108,"Yes") | G22: =COUNTIFS('📝 Visit Log'!$B$9:$B$108,A22,'📝 Visit Log'!$L$9:$L$108,"No") | I22: =COUNTIFS('📝 Visit Log'!$B$9:$B$108,A22,'📝 Visit Log'!$K$9:$K$108,"🔄 In Progress") | K22: =COUNTIFS('📝 Visit Log'!$B$9:$B$108,A22,'📝 Visit Log'!$Q$9:$Q$108,"🔴 Critical") | M22: =SUMIF('📝 Visit Log'!$B$9:$B$108,A22,'📝 Visit Log'!$O$9:$O$108) | O22: =COUNTIFS('📝 Visit Log'!$B$9:$B$108,A22,'📝 Visit Log'!$P$9:$P$108,"<>"&"")
A23: TOTAL | C23: =SUM(C11:C22) | E23: =SUM(E11:E22) | G23: =SUM(G11:G22) | I23: =SUM(I11:I22) | K23: =SUM(K11:K22) | M23: =SUM(M11:M22) | O23: =SUM(O11:O22)
A25: ━━ REPORT ACKNOWLEDGEMENT & SIGN-OFF ━━
A26: 🔧 TECHNICIAN / ENGINEER | H26: ✅ CLIENT / ADMIN COUNTER-SIGNATURE
A27: Name: ___________________________ Signature: ___________________________ Date: _______________ | H27: Name: ___________________________ Designation: ___________________________ Signature: ___________________________ Date: _______________
A29: DECLARATION
A30: I/We confirm that issues, actions and findings documented in this report are accurate and reflect the work carried out during this visit. Outstanding items have been communicated. Both parties agree to the contents of this report.
